<?xml version="1.0" encoding="UTF-8"?>
<!-- Generated by org.testng.reporters.JUnitReportReporter -->
<testsuite hostname="lgvn14663" name="rakuten.SignOutVerification" tests="1" failures="0" timestamp="15 Apr 2015 09:55:53 GMT" time="146.061" errors="1">
  <testcase name="TC_Point_Club_Verification" time="146.061" classname="rakuten.SignOutVerification">
    <error type="java.lang.AssertionError" message="expected [https://secure.rakuten.es/member/signin?service_id=Member] but found [https://secure.rakuten.es/member/signin]">
      <![CDATA[java.lang.AssertionError: expected [https://secure.rakuten.es/member/signin?service_id=Member] but found [https://secure.rakuten.es/member/signin]
	at org.testng.Assert.fail(Assert.java:94)
	at org.testng.Assert.failNotEquals(Assert.java:494)
	at org.testng.Assert.assertEquals(Assert.java:123)
	at org.testng.Assert.assertEquals(Assert.java:165)
	at com.logigear.selenium.QTiumAssert.verifyEquals(QTiumAssert.java:54)
	at com.logigear.selenium.QTiumAssert.verifyEquals(QTiumAssert.java:67)
	at rakuten.SignOutPageAction.VerifyUrl(SignOutPageAction.java:40)
	at rakuten.SignOutVerification_M.TC_Point_Club_Verification(SignOutVerification_M.java:47)
	at sun.reflect.NativeMethodAccessorImpl.invoke0(Native Method)
	at sun.reflect.NativeMethodAccessorImpl.invoke(Unknown Source)
	at sun.reflect.DelegatingMethodAccessorImpl.invoke(Unknown Source)
	at java.lang.reflect.Method.invoke(Unknown Source)
	at org.testng.internal.MethodInvocationHelper.invokeMethod(MethodInvocationHelper.java:84)
	at org.testng.internal.Invoker.invokeMethod(Invoker.java:714)
	at org.testng.internal.Invoker.invokeTestMethod(Invoker.java:901)
	at org.testng.internal.Invoker.invokeTestMethods(Invoker.java:1231)
	at org.testng.internal.TestMethodWorker.invokeTestMethods(TestMethodWorker.java:127)
	at org.testng.internal.TestMethodWorker.run(TestMethodWorker.java:111)
	at org.testng.TestRunner.privateRun(TestRunner.java:767)
	at org.testng.TestRunner.run(TestRunner.java:617)
	at org.testng.SuiteRunner.runTest(SuiteRunner.java:334)
	at org.testng.SuiteRunner.access$000(SuiteRunner.java:37)
	at org.testng.SuiteRunner$SuiteWorker.run(SuiteRunner.java:368)
	at org.testng.internal.thread.ThreadUtil$2.call(ThreadUtil.java:64)
	at java.util.concurrent.FutureTask.run(Unknown Source)
	at java.util.concurrent.ThreadPoolExecutor.runWorker(Unknown Source)
	at java.util.concurrent.ThreadPoolExecutor$Worker.run(Unknown Source)
	at java.lang.Thread.run(Unknown Source)
]]>
    </error>
  </testcase> <!-- TC_Point_Club_Verification -->
</testsuite> <!-- rakuten.SignOutVerification -->
